[2025-01-28T00:28:13.156+0000] {local_task_job_runner.py:123} INFO - ::group::Pre task execution logs
[2025-01-28T00:28:13.267+0000] {taskinstance.py:2613} INFO - Dependencies all met for dep_context=non-requeueable deps ti=<TaskInstance: raw_api_sales_data.store_sales_data_raw manual__2025-01-28T00:27:20.605187+00:00 [queued]>
[2025-01-28T00:28:13.317+0000] {taskinstance.py:2613} INFO - Dependencies all met for dep_context=requeueable deps ti=<TaskInstance: raw_api_sales_data.store_sales_data_raw manual__2025-01-28T00:27:20.605187+00:00 [queued]>
[2025-01-28T00:28:13.323+0000] {taskinstance.py:2866} INFO - Starting attempt 1 of 2
[2025-01-28T00:28:13.954+0000] {taskinstance.py:2889} INFO - Executing <Task(PythonOperator): store_sales_data_raw> on 2025-01-28 00:27:20.605187+00:00
[2025-01-28T00:28:13.990+0000] {warnings.py:112} WARNING - /home/***/.local/lib/python3.12/site-packages/***/task/task_runner/standard_task_runner.py:70: DeprecationWarning: This process (pid=1878) is multi-threaded, use of fork() may lead to deadlocks in the child.
  pid = os.fork()

[2025-01-28T00:28:13.991+0000] {standard_task_runner.py:104} INFO - Running: ['***', 'tasks', 'run', 'raw_api_sales_data', 'store_sales_data_raw', 'manual__2025-01-28T00:27:20.605187+00:00', '--job-id', '95', '--raw', '--subdir', 'DAGS_FOLDER/raw/dag_load_sales_data_to_db.py', '--cfg-path', '/tmp/tmp356azi1l']
[2025-01-28T00:28:13.994+0000] {standard_task_runner.py:72} INFO - Started process 1880 to run task
[2025-01-28T00:28:13.994+0000] {standard_task_runner.py:105} INFO - Job 95: Subtask store_sales_data_raw
[2025-01-28T00:28:14.257+0000] {task_command.py:467} INFO - Running <TaskInstance: raw_api_sales_data.store_sales_data_raw manual__2025-01-28T00:27:20.605187+00:00 [running]> on host 1de8b92bf5f9
[2025-01-28T00:28:14.731+0000] {taskinstance.py:3132} INFO - Exporting env vars: AIRFLOW_CTX_DAG_OWNER='***' AIRFLOW_CTX_DAG_ID='raw_api_sales_data' AIRFLOW_CTX_TASK_ID='store_sales_data_raw' AIRFLOW_CTX_EXECUTION_DATE='2025-01-28T00:27:20.605187+00:00' AIRFLOW_CTX_TRY_NUMBER='1' AIRFLOW_CTX_DAG_RUN_ID='manual__2025-01-28T00:27:20.605187+00:00'
[2025-01-28T00:28:14.737+0000] {logging_mixin.py:190} INFO - Task instance is in running state
[2025-01-28T00:28:14.742+0000] {logging_mixin.py:190} INFO -  Previous state of the Task instance: queued
[2025-01-28T00:28:14.747+0000] {logging_mixin.py:190} INFO - Current task name:store_sales_data_raw state:running start_date:2025-01-28 00:28:13.269270+00:00
[2025-01-28T00:28:14.749+0000] {logging_mixin.py:190} INFO - Dag name:raw_api_sales_data and current dag run status:running
[2025-01-28T00:28:14.751+0000] {taskinstance.py:731} INFO - ::endgroup::
[2025-01-28T00:28:15.697+0000] {database_helpers.py:20} INFO - Connected to PostgreSQL database.
[2025-01-28T00:28:15.699+0000] {database_helpers.py:93} ERROR - Failed to insert data into raw_layer.sales: 'list' object is not callable
[2025-01-28T00:28:15.701+0000] {raw_store_sales_data.py:34} ERROR - Failed to insert data to a table : 'list' object is not callable
[2025-01-28T00:28:15.704+0000] {database_helpers.py:30} INFO - Closed the database connection.
[2025-01-28T00:28:15.707+0000] {raw_store_sales_data.py:38} INFO - Database Closed
[2025-01-28T00:28:15.716+0000] {taskinstance.py:3311} ERROR - Task failed with exception
Traceback (most recent call last):
  File "/home/airflow/.local/lib/python3.12/site-packages/airflow/models/taskinstance.py", line 767, in _execute_task
    result = _execute_callable(context=context, **execute_callable_kwargs)
             ^^^^^^^^^^^^^^^^^^^^^^^^^^^^^^^^^^^^^^^^^^^^^^^^^^^^^^^^^^^^^
  File "/home/airflow/.local/lib/python3.12/site-packages/airflow/models/taskinstance.py", line 733, in _execute_callable
    return ExecutionCallableRunner(
           ^^^^^^^^^^^^^^^^^^^^^^^^
  File "/home/airflow/.local/lib/python3.12/site-packages/airflow/utils/operator_helpers.py", line 252, in run
    return self.func(*args, **kwargs)
           ^^^^^^^^^^^^^^^^^^^^^^^^^^
  File "/home/airflow/.local/lib/python3.12/site-packages/airflow/models/baseoperator.py", line 422, in wrapper
    return func(self, *args, **kwargs)
           ^^^^^^^^^^^^^^^^^^^^^^^^^^^
  File "/home/airflow/.local/lib/python3.12/site-packages/airflow/operators/python.py", line 238, in execute
    return_value = self.execute_callable()
                   ^^^^^^^^^^^^^^^^^^^^^^^
  File "/home/airflow/.local/lib/python3.12/site-packages/airflow/operators/python.py", line 256, in execute_callable
    return runner.run(*self.op_args, **self.op_kwargs)
           ^^^^^^^^^^^^^^^^^^^^^^^^^^^^^^^^^^^^^^^^^^^
  File "/home/airflow/.local/lib/python3.12/site-packages/airflow/utils/operator_helpers.py", line 252, in run
    return self.func(*args, **kwargs)
           ^^^^^^^^^^^^^^^^^^^^^^^^^^
  File "/opt/airflow/dags/logic/raw_store_sales_data.py", line 30, in store_api_sales_data
    insert_data(conn, "raw_layer.sales", columns, registry)
  File "/opt/airflow/dags/helpers/database_helpers.py", line 89, in insert_data
    conn.cursor(query, registry)
TypeError: 'list' object is not callable
[2025-01-28T00:28:15.893+0000] {logging_mixin.py:190} INFO - Task instance in failure state
[2025-01-28T00:28:15.898+0000] {logging_mixin.py:190} INFO - Task start:2025-01-28 00:28:13.269270+00:00 end:2025-01-28 00:28:15.872390+00:00 duration:2.60312
[2025-01-28T00:28:15.903+0000] {logging_mixin.py:190} INFO - Task:<Task(PythonOperator): store_sales_data_raw> dag:<DAG: raw_api_sales_data> dagrun:<DagRun raw_api_sales_data @ 2025-01-28 00:27:20.605187+00:00: manual__2025-01-28T00:27:20.605187+00:00, state:running, queued_at: 2025-01-28 00:27:20.838275+00:00. externally triggered: True>
[2025-01-28T00:28:15.905+0000] {logging_mixin.py:190} INFO - Failure caused by 'list' object is not callable
[2025-01-28T00:28:15.907+0000] {taskinstance.py:1225} INFO - Marking task as UP_FOR_RETRY. dag_id=raw_api_sales_data, task_id=store_sales_data_raw, run_id=manual__2025-01-28T00:27:20.605187+00:00, execution_date=20250128T002720, start_date=20250128T002813, end_date=20250128T002815
[2025-01-28T00:28:16.067+0000] {taskinstance.py:340} INFO - ::group::Post task execution logs
[2025-01-28T00:28:16.072+0000] {standard_task_runner.py:124} ERROR - Failed to execute job 95 for task store_sales_data_raw ('list' object is not callable; 1880)
Traceback (most recent call last):
  File "/home/airflow/.local/lib/python3.12/site-packages/airflow/task/task_runner/standard_task_runner.py", line 117, in _start_by_fork
    ret = args.func(args, dag=self.dag)
          ^^^^^^^^^^^^^^^^^^^^^^^^^^^^^
  File "/home/airflow/.local/lib/python3.12/site-packages/airflow/cli/cli_config.py", line 49, in command
    return func(*args, **kwargs)
           ^^^^^^^^^^^^^^^^^^^^^
  File "/home/airflow/.local/lib/python3.12/site-packages/airflow/utils/cli.py", line 116, in wrapper
    return f(*args, **kwargs)
           ^^^^^^^^^^^^^^^^^^
  File "/home/airflow/.local/lib/python3.12/site-packages/airflow/cli/commands/task_command.py", line 483, in task_run
    task_return_code = _run_task_by_selected_method(args, _dag, ti)
                       ^^^^^^^^^^^^^^^^^^^^^^^^^^^^^^^^^^^^^^^^^^^^
  File "/home/airflow/.local/lib/python3.12/site-packages/airflow/cli/commands/task_command.py", line 256, in _run_task_by_selected_method
    return _run_raw_task(args, ti)
           ^^^^^^^^^^^^^^^^^^^^^^^
  File "/home/airflow/.local/lib/python3.12/site-packages/airflow/cli/commands/task_command.py", line 341, in _run_raw_task
    return ti._run_raw_task(
           ^^^^^^^^^^^^^^^^^
  File "/home/airflow/.local/lib/python3.12/site-packages/airflow/utils/session.py", line 97, in wrapper
    return func(*args, session=session, **kwargs)
           ^^^^^^^^^^^^^^^^^^^^^^^^^^^^^^^^^^^^^^
  File "/home/airflow/.local/lib/python3.12/site-packages/airflow/models/taskinstance.py", line 3005, in _run_raw_task
    return _run_raw_task(
           ^^^^^^^^^^^^^^
  File "/home/airflow/.local/lib/python3.12/site-packages/airflow/models/taskinstance.py", line 273, in _run_raw_task
    TaskInstance._execute_task_with_callbacks(
  File "/home/airflow/.local/lib/python3.12/site-packages/airflow/models/taskinstance.py", line 3159, in _execute_task_with_callbacks
    result = self._execute_task(context, task_orig)
             ^^^^^^^^^^^^^^^^^^^^^^^^^^^^^^^^^^^^^^
  File "/home/airflow/.local/lib/python3.12/site-packages/airflow/models/taskinstance.py", line 3183, in _execute_task
    return _execute_task(self, context, task_orig)
           ^^^^^^^^^^^^^^^^^^^^^^^^^^^^^^^^^^^^^^^
  File "/home/airflow/.local/lib/python3.12/site-packages/airflow/models/taskinstance.py", line 767, in _execute_task
    result = _execute_callable(context=context, **execute_callable_kwargs)
             ^^^^^^^^^^^^^^^^^^^^^^^^^^^^^^^^^^^^^^^^^^^^^^^^^^^^^^^^^^^^^
  File "/home/airflow/.local/lib/python3.12/site-packages/airflow/models/taskinstance.py", line 733, in _execute_callable
    return ExecutionCallableRunner(
           ^^^^^^^^^^^^^^^^^^^^^^^^
  File "/home/airflow/.local/lib/python3.12/site-packages/airflow/utils/operator_helpers.py", line 252, in run
    return self.func(*args, **kwargs)
           ^^^^^^^^^^^^^^^^^^^^^^^^^^
  File "/home/airflow/.local/lib/python3.12/site-packages/airflow/models/baseoperator.py", line 422, in wrapper
    return func(self, *args, **kwargs)
           ^^^^^^^^^^^^^^^^^^^^^^^^^^^
  File "/home/airflow/.local/lib/python3.12/site-packages/airflow/operators/python.py", line 238, in execute
    return_value = self.execute_callable()
                   ^^^^^^^^^^^^^^^^^^^^^^^
  File "/home/airflow/.local/lib/python3.12/site-packages/airflow/operators/python.py", line 256, in execute_callable
    return runner.run(*self.op_args, **self.op_kwargs)
           ^^^^^^^^^^^^^^^^^^^^^^^^^^^^^^^^^^^^^^^^^^^
  File "/home/airflow/.local/lib/python3.12/site-packages/airflow/utils/operator_helpers.py", line 252, in run
    return self.func(*args, **kwargs)
           ^^^^^^^^^^^^^^^^^^^^^^^^^^
  File "/opt/airflow/dags/logic/raw_store_sales_data.py", line 30, in store_api_sales_data
    insert_data(conn, "raw_layer.sales", columns, registry)
  File "/opt/airflow/dags/helpers/database_helpers.py", line 89, in insert_data
    conn.cursor(query, registry)
TypeError: 'list' object is not callable
[2025-01-28T00:28:16.329+0000] {local_task_job_runner.py:266} INFO - Task exited with return code 1
[2025-01-28T00:28:16.512+0000] {taskinstance.py:3895} INFO - 0 downstream tasks scheduled from follow-on schedule check
[2025-01-28T00:28:16.524+0000] {local_task_job_runner.py:245} INFO - ::endgroup::
