[2025-01-28T19:17:58.738+0000] {local_task_job_runner.py:123} INFO - ::group::Pre task execution logs
[2025-01-28T19:17:58.783+0000] {taskinstance.py:2613} INFO - Dependencies all met for dep_context=non-requeueable deps ti=<TaskInstance: raw_api_sales_data.store_sales_data_raw manual__2025-01-28T19:17:16.874796+00:00 [queued]>
[2025-01-28T19:17:58.807+0000] {taskinstance.py:2613} INFO - Dependencies all met for dep_context=requeueable deps ti=<TaskInstance: raw_api_sales_data.store_sales_data_raw manual__2025-01-28T19:17:16.874796+00:00 [queued]>
[2025-01-28T19:17:58.810+0000] {taskinstance.py:2866} INFO - Starting attempt 2 of 2
[2025-01-28T19:17:58.858+0000] {taskinstance.py:2889} INFO - Executing <Task(PythonOperator): store_sales_data_raw> on 2025-01-28 19:17:16.874796+00:00
[2025-01-28T19:17:58.884+0000] {warnings.py:112} WARNING - /home/***/.local/lib/python3.12/site-packages/***/task/task_runner/standard_task_runner.py:70: DeprecationWarning: This process (pid=4797) is multi-threaded, use of fork() may lead to deadlocks in the child.
  pid = os.fork()

[2025-01-28T19:17:58.888+0000] {standard_task_runner.py:72} INFO - Started process 4799 to run task
[2025-01-28T19:17:58.891+0000] {standard_task_runner.py:104} INFO - Running: ['***', 'tasks', 'run', 'raw_api_sales_data', 'store_sales_data_raw', 'manual__2025-01-28T19:17:16.874796+00:00', '--job-id', '165', '--raw', '--subdir', 'DAGS_FOLDER/raw/dag_load_sales_data_to_db.py', '--cfg-path', '/tmp/tmpg2us29ix']
[2025-01-28T19:17:58.895+0000] {standard_task_runner.py:105} INFO - Job 165: Subtask store_sales_data_raw
[2025-01-28T19:17:59.044+0000] {task_command.py:467} INFO - Running <TaskInstance: raw_api_sales_data.store_sales_data_raw manual__2025-01-28T19:17:16.874796+00:00 [running]> on host 1de8b92bf5f9
[2025-01-28T19:17:59.228+0000] {taskinstance.py:3132} INFO - Exporting env vars: AIRFLOW_CTX_DAG_OWNER='***' AIRFLOW_CTX_DAG_ID='raw_api_sales_data' AIRFLOW_CTX_TASK_ID='store_sales_data_raw' AIRFLOW_CTX_EXECUTION_DATE='2025-01-28T19:17:16.874796+00:00' AIRFLOW_CTX_TRY_NUMBER='2' AIRFLOW_CTX_DAG_RUN_ID='manual__2025-01-28T19:17:16.874796+00:00'
[2025-01-28T19:17:59.231+0000] {logging_mixin.py:190} INFO - Task instance is in running state
[2025-01-28T19:17:59.233+0000] {logging_mixin.py:190} INFO -  Previous state of the Task instance: queued
[2025-01-28T19:17:59.234+0000] {logging_mixin.py:190} INFO - Current task name:store_sales_data_raw state:running start_date:2025-01-28 19:17:58.784504+00:00
[2025-01-28T19:17:59.236+0000] {logging_mixin.py:190} INFO - Dag name:raw_api_sales_data and current dag run status:running
[2025-01-28T19:17:59.237+0000] {taskinstance.py:731} INFO - ::endgroup::
[2025-01-28T19:17:59.677+0000] {database_helpers.py:21} INFO - Connected to PostgreSQL database.
[2025-01-28T19:17:59.678+0000] {raw_store_sales_data.py:35} ERROR - Failed to insert data to a table : initial_value must be str or None, not datetime.datetime
[2025-01-28T19:17:59.679+0000] {database_helpers.py:31} INFO - Closed the database connection.
[2025-01-28T19:17:59.681+0000] {raw_store_sales_data.py:39} INFO - Database Closed
[2025-01-28T19:17:59.683+0000] {taskinstance.py:3311} ERROR - Task failed with exception
Traceback (most recent call last):
  File "/home/airflow/.local/lib/python3.12/site-packages/airflow/models/taskinstance.py", line 767, in _execute_task
    result = _execute_callable(context=context, **execute_callable_kwargs)
             ^^^^^^^^^^^^^^^^^^^^^^^^^^^^^^^^^^^^^^^^^^^^^^^^^^^^^^^^^^^^^
  File "/home/airflow/.local/lib/python3.12/site-packages/airflow/models/taskinstance.py", line 733, in _execute_callable
    return ExecutionCallableRunner(
           ^^^^^^^^^^^^^^^^^^^^^^^^
  File "/home/airflow/.local/lib/python3.12/site-packages/airflow/utils/operator_helpers.py", line 252, in run
    return self.func(*args, **kwargs)
           ^^^^^^^^^^^^^^^^^^^^^^^^^^
  File "/home/airflow/.local/lib/python3.12/site-packages/airflow/models/baseoperator.py", line 422, in wrapper
    return func(self, *args, **kwargs)
           ^^^^^^^^^^^^^^^^^^^^^^^^^^^
  File "/home/airflow/.local/lib/python3.12/site-packages/airflow/operators/python.py", line 238, in execute
    return_value = self.execute_callable()
                   ^^^^^^^^^^^^^^^^^^^^^^^
  File "/home/airflow/.local/lib/python3.12/site-packages/airflow/operators/python.py", line 256, in execute_callable
    return runner.run(*self.op_args, **self.op_kwargs)
           ^^^^^^^^^^^^^^^^^^^^^^^^^^^^^^^^^^^^^^^^^^^
  File "/home/airflow/.local/lib/python3.12/site-packages/airflow/utils/operator_helpers.py", line 252, in run
    return self.func(*args, **kwargs)
           ^^^^^^^^^^^^^^^^^^^^^^^^^^
  File "/opt/airflow/dags/logic/raw_store_sales_data.py", line 28, in store_api_sales_data
    d[columns[11]], d[columns[12]], StringIO(ingestion_time)
                                    ^^^^^^^^^^^^^^^^^^^^^^^^
TypeError: initial_value must be str or None, not datetime.datetime
[2025-01-28T19:17:59.717+0000] {logging_mixin.py:190} INFO - Task instance in failure state
[2025-01-28T19:17:59.718+0000] {logging_mixin.py:190} INFO - Task start:2025-01-28 19:17:58.784504+00:00 end:2025-01-28 19:17:59.716249+00:00 duration:0.931745
[2025-01-28T19:17:59.719+0000] {logging_mixin.py:190} INFO - Task:<Task(PythonOperator): store_sales_data_raw> dag:<DAG: raw_api_sales_data> dagrun:<DagRun raw_api_sales_data @ 2025-01-28 19:17:16.874796+00:00: manual__2025-01-28T19:17:16.874796+00:00, state:running, queued_at: 2025-01-28 19:17:17.835600+00:00. externally triggered: True>
[2025-01-28T19:17:59.720+0000] {logging_mixin.py:190} INFO - Failure caused by initial_value must be str or None, not datetime.datetime
[2025-01-28T19:17:59.722+0000] {taskinstance.py:1225} INFO - Marking task as FAILED. dag_id=raw_api_sales_data, task_id=store_sales_data_raw, run_id=manual__2025-01-28T19:17:16.874796+00:00, execution_date=20250128T191716, start_date=20250128T191758, end_date=20250128T191759
[2025-01-28T19:17:59.751+0000] {taskinstance.py:340} INFO - ::group::Post task execution logs
[2025-01-28T19:17:59.753+0000] {standard_task_runner.py:124} ERROR - Failed to execute job 165 for task store_sales_data_raw (initial_value must be str or None, not datetime.datetime; 4799)
Traceback (most recent call last):
  File "/home/airflow/.local/lib/python3.12/site-packages/airflow/task/task_runner/standard_task_runner.py", line 117, in _start_by_fork
    ret = args.func(args, dag=self.dag)
          ^^^^^^^^^^^^^^^^^^^^^^^^^^^^^
  File "/home/airflow/.local/lib/python3.12/site-packages/airflow/cli/cli_config.py", line 49, in command
    return func(*args, **kwargs)
           ^^^^^^^^^^^^^^^^^^^^^
  File "/home/airflow/.local/lib/python3.12/site-packages/airflow/utils/cli.py", line 116, in wrapper
    return f(*args, **kwargs)
           ^^^^^^^^^^^^^^^^^^
  File "/home/airflow/.local/lib/python3.12/site-packages/airflow/cli/commands/task_command.py", line 483, in task_run
    task_return_code = _run_task_by_selected_method(args, _dag, ti)
                       ^^^^^^^^^^^^^^^^^^^^^^^^^^^^^^^^^^^^^^^^^^^^
  File "/home/airflow/.local/lib/python3.12/site-packages/airflow/cli/commands/task_command.py", line 256, in _run_task_by_selected_method
    return _run_raw_task(args, ti)
           ^^^^^^^^^^^^^^^^^^^^^^^
  File "/home/airflow/.local/lib/python3.12/site-packages/airflow/cli/commands/task_command.py", line 341, in _run_raw_task
    return ti._run_raw_task(
           ^^^^^^^^^^^^^^^^^
  File "/home/airflow/.local/lib/python3.12/site-packages/airflow/utils/session.py", line 97, in wrapper
    return func(*args, session=session, **kwargs)
           ^^^^^^^^^^^^^^^^^^^^^^^^^^^^^^^^^^^^^^
  File "/home/airflow/.local/lib/python3.12/site-packages/airflow/models/taskinstance.py", line 3005, in _run_raw_task
    return _run_raw_task(
           ^^^^^^^^^^^^^^
  File "/home/airflow/.local/lib/python3.12/site-packages/airflow/models/taskinstance.py", line 273, in _run_raw_task
    TaskInstance._execute_task_with_callbacks(
  File "/home/airflow/.local/lib/python3.12/site-packages/airflow/models/taskinstance.py", line 3159, in _execute_task_with_callbacks
    result = self._execute_task(context, task_orig)
             ^^^^^^^^^^^^^^^^^^^^^^^^^^^^^^^^^^^^^^
  File "/home/airflow/.local/lib/python3.12/site-packages/airflow/models/taskinstance.py", line 3183, in _execute_task
    return _execute_task(self, context, task_orig)
           ^^^^^^^^^^^^^^^^^^^^^^^^^^^^^^^^^^^^^^^
  File "/home/airflow/.local/lib/python3.12/site-packages/airflow/models/taskinstance.py", line 767, in _execute_task
    result = _execute_callable(context=context, **execute_callable_kwargs)
             ^^^^^^^^^^^^^^^^^^^^^^^^^^^^^^^^^^^^^^^^^^^^^^^^^^^^^^^^^^^^^
  File "/home/airflow/.local/lib/python3.12/site-packages/airflow/models/taskinstance.py", line 733, in _execute_callable
    return ExecutionCallableRunner(
           ^^^^^^^^^^^^^^^^^^^^^^^^
  File "/home/airflow/.local/lib/python3.12/site-packages/airflow/utils/operator_helpers.py", line 252, in run
    return self.func(*args, **kwargs)
           ^^^^^^^^^^^^^^^^^^^^^^^^^^
  File "/home/airflow/.local/lib/python3.12/site-packages/airflow/models/baseoperator.py", line 422, in wrapper
    return func(self, *args, **kwargs)
           ^^^^^^^^^^^^^^^^^^^^^^^^^^^
  File "/home/airflow/.local/lib/python3.12/site-packages/airflow/operators/python.py", line 238, in execute
    return_value = self.execute_callable()
                   ^^^^^^^^^^^^^^^^^^^^^^^
  File "/home/airflow/.local/lib/python3.12/site-packages/airflow/operators/python.py", line 256, in execute_callable
    return runner.run(*self.op_args, **self.op_kwargs)
           ^^^^^^^^^^^^^^^^^^^^^^^^^^^^^^^^^^^^^^^^^^^
  File "/home/airflow/.local/lib/python3.12/site-packages/airflow/utils/operator_helpers.py", line 252, in run
    return self.func(*args, **kwargs)
           ^^^^^^^^^^^^^^^^^^^^^^^^^^
  File "/opt/airflow/dags/logic/raw_store_sales_data.py", line 28, in store_api_sales_data
    d[columns[11]], d[columns[12]], StringIO(ingestion_time)
                                    ^^^^^^^^^^^^^^^^^^^^^^^^
TypeError: initial_value must be str or None, not datetime.datetime
[2025-01-28T19:17:59.793+0000] {local_task_job_runner.py:266} INFO - Task exited with return code 1
[2025-01-28T19:17:59.838+0000] {taskinstance.py:3895} INFO - 0 downstream tasks scheduled from follow-on schedule check
[2025-01-28T19:17:59.846+0000] {local_task_job_runner.py:245} INFO - ::endgroup::
