[2025-01-28T00:22:42.523+0000] {local_task_job_runner.py:123} INFO - ::group::Pre task execution logs
[2025-01-28T00:22:42.634+0000] {taskinstance.py:2613} INFO - Dependencies all met for dep_context=non-requeueable deps ti=<TaskInstance: raw_api_sales_data.store_sales_data_raw manual__2025-01-28T00:22:04.610217+00:00 [queued]>
[2025-01-28T00:22:42.712+0000] {taskinstance.py:2613} INFO - Dependencies all met for dep_context=requeueable deps ti=<TaskInstance: raw_api_sales_data.store_sales_data_raw manual__2025-01-28T00:22:04.610217+00:00 [queued]>
[2025-01-28T00:22:42.718+0000] {taskinstance.py:2866} INFO - Starting attempt 2 of 2
[2025-01-28T00:22:43.256+0000] {taskinstance.py:2889} INFO - Executing <Task(PythonOperator): store_sales_data_raw> on 2025-01-28 00:22:04.610217+00:00
[2025-01-28T00:22:43.274+0000] {warnings.py:112} WARNING - /home/***/.local/lib/python3.12/site-packages/***/task/task_runner/standard_task_runner.py:70: DeprecationWarning: This process (pid=1814) is multi-threaded, use of fork() may lead to deadlocks in the child.
  pid = os.fork()

[2025-01-28T00:22:43.278+0000] {standard_task_runner.py:72} INFO - Started process 1816 to run task
[2025-01-28T00:22:43.280+0000] {standard_task_runner.py:104} INFO - Running: ['***', 'tasks', 'run', 'raw_api_sales_data', 'store_sales_data_raw', 'manual__2025-01-28T00:22:04.610217+00:00', '--job-id', '93', '--raw', '--subdir', 'DAGS_FOLDER/raw/dag_load_sales_data_to_db.py', '--cfg-path', '/tmp/tmpl8bl0k2t']
[2025-01-28T00:22:43.284+0000] {standard_task_runner.py:105} INFO - Job 93: Subtask store_sales_data_raw
[2025-01-28T00:22:43.449+0000] {task_command.py:467} INFO - Running <TaskInstance: raw_api_sales_data.store_sales_data_raw manual__2025-01-28T00:22:04.610217+00:00 [running]> on host 1de8b92bf5f9
[2025-01-28T00:22:43.774+0000] {taskinstance.py:3132} INFO - Exporting env vars: AIRFLOW_CTX_DAG_OWNER='***' AIRFLOW_CTX_DAG_ID='raw_api_sales_data' AIRFLOW_CTX_TASK_ID='store_sales_data_raw' AIRFLOW_CTX_EXECUTION_DATE='2025-01-28T00:22:04.610217+00:00' AIRFLOW_CTX_TRY_NUMBER='2' AIRFLOW_CTX_DAG_RUN_ID='manual__2025-01-28T00:22:04.610217+00:00'
[2025-01-28T00:22:43.777+0000] {logging_mixin.py:190} INFO - Task instance is in running state
[2025-01-28T00:22:43.779+0000] {logging_mixin.py:190} INFO -  Previous state of the Task instance: queued
[2025-01-28T00:22:43.780+0000] {logging_mixin.py:190} INFO - Current task name:store_sales_data_raw state:running start_date:2025-01-28 00:22:42.637852+00:00
[2025-01-28T00:22:43.782+0000] {logging_mixin.py:190} INFO - Dag name:raw_api_sales_data and current dag run status:running
[2025-01-28T00:22:43.784+0000] {taskinstance.py:731} INFO - ::endgroup::
[2025-01-28T00:22:44.131+0000] {database_helpers.py:20} INFO - Connected to PostgreSQL database.
[2025-01-28T00:22:44.134+0000] {raw_store_sales_data.py:34} ERROR - Failed to insert data to a table : cannot access local variable 'registry' where it is not associated with a value
[2025-01-28T00:22:44.136+0000] {database_helpers.py:30} INFO - Closed the database connection.
[2025-01-28T00:22:44.137+0000] {raw_store_sales_data.py:38} INFO - Database Closed
[2025-01-28T00:22:44.139+0000] {taskinstance.py:3311} ERROR - Task failed with exception
Traceback (most recent call last):
  File "/home/airflow/.local/lib/python3.12/site-packages/airflow/models/taskinstance.py", line 767, in _execute_task
    result = _execute_callable(context=context, **execute_callable_kwargs)
             ^^^^^^^^^^^^^^^^^^^^^^^^^^^^^^^^^^^^^^^^^^^^^^^^^^^^^^^^^^^^^
  File "/home/airflow/.local/lib/python3.12/site-packages/airflow/models/taskinstance.py", line 733, in _execute_callable
    return ExecutionCallableRunner(
           ^^^^^^^^^^^^^^^^^^^^^^^^
  File "/home/airflow/.local/lib/python3.12/site-packages/airflow/utils/operator_helpers.py", line 252, in run
    return self.func(*args, **kwargs)
           ^^^^^^^^^^^^^^^^^^^^^^^^^^
  File "/home/airflow/.local/lib/python3.12/site-packages/airflow/models/baseoperator.py", line 422, in wrapper
    return func(self, *args, **kwargs)
           ^^^^^^^^^^^^^^^^^^^^^^^^^^^
  File "/home/airflow/.local/lib/python3.12/site-packages/airflow/operators/python.py", line 238, in execute
    return_value = self.execute_callable()
                   ^^^^^^^^^^^^^^^^^^^^^^^
  File "/home/airflow/.local/lib/python3.12/site-packages/airflow/operators/python.py", line 256, in execute_callable
    return runner.run(*self.op_args, **self.op_kwargs)
           ^^^^^^^^^^^^^^^^^^^^^^^^^^^^^^^^^^^^^^^^^^^
  File "/home/airflow/.local/lib/python3.12/site-packages/airflow/utils/operator_helpers.py", line 252, in run
    return self.func(*args, **kwargs)
           ^^^^^^^^^^^^^^^^^^^^^^^^^^
  File "/opt/airflow/dags/logic/raw_store_sales_data.py", line 30, in store_api_sales_data
    insert_data(conn, "raw_layer.sales", columns, registry)
                                                  ^^^^^^^^
UnboundLocalError: cannot access local variable 'registry' where it is not associated with a value
[2025-01-28T00:22:44.192+0000] {logging_mixin.py:190} INFO - Task instance in failure state
[2025-01-28T00:22:44.194+0000] {logging_mixin.py:190} INFO - Task start:2025-01-28 00:22:42.637852+00:00 end:2025-01-28 00:22:44.191088+00:00 duration:1.553236
[2025-01-28T00:22:44.196+0000] {logging_mixin.py:190} INFO - Task:<Task(PythonOperator): store_sales_data_raw> dag:<DAG: raw_api_sales_data> dagrun:<DagRun raw_api_sales_data @ 2025-01-28 00:22:04.610217+00:00: manual__2025-01-28T00:22:04.610217+00:00, state:running, queued_at: 2025-01-28 00:22:04.699334+00:00. externally triggered: True>
[2025-01-28T00:22:44.197+0000] {logging_mixin.py:190} INFO - Failure caused by cannot access local variable 'registry' where it is not associated with a value
[2025-01-28T00:22:44.204+0000] {taskinstance.py:1225} INFO - Marking task as FAILED. dag_id=raw_api_sales_data, task_id=store_sales_data_raw, run_id=manual__2025-01-28T00:22:04.610217+00:00, execution_date=20250128T002204, start_date=20250128T002242, end_date=20250128T002244
[2025-01-28T00:22:44.268+0000] {taskinstance.py:340} INFO - ::group::Post task execution logs
[2025-01-28T00:22:44.273+0000] {standard_task_runner.py:124} ERROR - Failed to execute job 93 for task store_sales_data_raw (cannot access local variable 'registry' where it is not associated with a value; 1816)
Traceback (most recent call last):
  File "/home/airflow/.local/lib/python3.12/site-packages/airflow/task/task_runner/standard_task_runner.py", line 117, in _start_by_fork
    ret = args.func(args, dag=self.dag)
          ^^^^^^^^^^^^^^^^^^^^^^^^^^^^^
  File "/home/airflow/.local/lib/python3.12/site-packages/airflow/cli/cli_config.py", line 49, in command
    return func(*args, **kwargs)
           ^^^^^^^^^^^^^^^^^^^^^
  File "/home/airflow/.local/lib/python3.12/site-packages/airflow/utils/cli.py", line 116, in wrapper
    return f(*args, **kwargs)
           ^^^^^^^^^^^^^^^^^^
  File "/home/airflow/.local/lib/python3.12/site-packages/airflow/cli/commands/task_command.py", line 483, in task_run
    task_return_code = _run_task_by_selected_method(args, _dag, ti)
                       ^^^^^^^^^^^^^^^^^^^^^^^^^^^^^^^^^^^^^^^^^^^^
  File "/home/airflow/.local/lib/python3.12/site-packages/airflow/cli/commands/task_command.py", line 256, in _run_task_by_selected_method
    return _run_raw_task(args, ti)
           ^^^^^^^^^^^^^^^^^^^^^^^
  File "/home/airflow/.local/lib/python3.12/site-packages/airflow/cli/commands/task_command.py", line 341, in _run_raw_task
    return ti._run_raw_task(
           ^^^^^^^^^^^^^^^^^
  File "/home/airflow/.local/lib/python3.12/site-packages/airflow/utils/session.py", line 97, in wrapper
    return func(*args, session=session, **kwargs)
           ^^^^^^^^^^^^^^^^^^^^^^^^^^^^^^^^^^^^^^
  File "/home/airflow/.local/lib/python3.12/site-packages/airflow/models/taskinstance.py", line 3005, in _run_raw_task
    return _run_raw_task(
           ^^^^^^^^^^^^^^
  File "/home/airflow/.local/lib/python3.12/site-packages/airflow/models/taskinstance.py", line 273, in _run_raw_task
    TaskInstance._execute_task_with_callbacks(
  File "/home/airflow/.local/lib/python3.12/site-packages/airflow/models/taskinstance.py", line 3159, in _execute_task_with_callbacks
    result = self._execute_task(context, task_orig)
             ^^^^^^^^^^^^^^^^^^^^^^^^^^^^^^^^^^^^^^
  File "/home/airflow/.local/lib/python3.12/site-packages/airflow/models/taskinstance.py", line 3183, in _execute_task
    return _execute_task(self, context, task_orig)
           ^^^^^^^^^^^^^^^^^^^^^^^^^^^^^^^^^^^^^^^
  File "/home/airflow/.local/lib/python3.12/site-packages/airflow/models/taskinstance.py", line 767, in _execute_task
    result = _execute_callable(context=context, **execute_callable_kwargs)
             ^^^^^^^^^^^^^^^^^^^^^^^^^^^^^^^^^^^^^^^^^^^^^^^^^^^^^^^^^^^^^
  File "/home/airflow/.local/lib/python3.12/site-packages/airflow/models/taskinstance.py", line 733, in _execute_callable
    return ExecutionCallableRunner(
           ^^^^^^^^^^^^^^^^^^^^^^^^
  File "/home/airflow/.local/lib/python3.12/site-packages/airflow/utils/operator_helpers.py", line 252, in run
    return self.func(*args, **kwargs)
           ^^^^^^^^^^^^^^^^^^^^^^^^^^
  File "/home/airflow/.local/lib/python3.12/site-packages/airflow/models/baseoperator.py", line 422, in wrapper
    return func(self, *args, **kwargs)
           ^^^^^^^^^^^^^^^^^^^^^^^^^^^
  File "/home/airflow/.local/lib/python3.12/site-packages/airflow/operators/python.py", line 238, in execute
    return_value = self.execute_callable()
                   ^^^^^^^^^^^^^^^^^^^^^^^
  File "/home/airflow/.local/lib/python3.12/site-packages/airflow/operators/python.py", line 256, in execute_callable
    return runner.run(*self.op_args, **self.op_kwargs)
           ^^^^^^^^^^^^^^^^^^^^^^^^^^^^^^^^^^^^^^^^^^^
  File "/home/airflow/.local/lib/python3.12/site-packages/airflow/utils/operator_helpers.py", line 252, in run
    return self.func(*args, **kwargs)
           ^^^^^^^^^^^^^^^^^^^^^^^^^^
  File "/opt/airflow/dags/logic/raw_store_sales_data.py", line 30, in store_api_sales_data
    insert_data(conn, "raw_layer.sales", columns, registry)
                                                  ^^^^^^^^
UnboundLocalError: cannot access local variable 'registry' where it is not associated with a value
[2025-01-28T00:22:44.352+0000] {local_task_job_runner.py:266} INFO - Task exited with return code 1
[2025-01-28T00:22:44.391+0000] {taskinstance.py:3895} INFO - 0 downstream tasks scheduled from follow-on schedule check
[2025-01-28T00:22:44.398+0000] {local_task_job_runner.py:245} INFO - ::endgroup::
