[2025-01-27T22:13:49.225+0000] {local_task_job_runner.py:123} INFO - ::group::Pre task execution logs
[2025-01-27T22:13:49.269+0000] {taskinstance.py:2613} INFO - Dependencies all met for dep_context=non-requeueable deps ti=<TaskInstance: raw_api_sales_data.store_sales_data_raw manual__2025-01-27T22:12:59.881065+00:00 [queued]>
[2025-01-27T22:13:49.289+0000] {taskinstance.py:2613} INFO - Dependencies all met for dep_context=requeueable deps ti=<TaskInstance: raw_api_sales_data.store_sales_data_raw manual__2025-01-27T22:12:59.881065+00:00 [queued]>
[2025-01-27T22:13:49.291+0000] {taskinstance.py:2866} INFO - Starting attempt 1 of 2
[2025-01-27T22:13:49.595+0000] {taskinstance.py:2889} INFO - Executing <Task(PythonOperator): store_sales_data_raw> on 2025-01-27 22:12:59.881065+00:00
[2025-01-27T22:13:49.613+0000] {warnings.py:112} WARNING - /home/***/.local/lib/python3.12/site-packages/***/task/task_runner/standard_task_runner.py:70: DeprecationWarning: This process (pid=220) is multi-threaded, use of fork() may lead to deadlocks in the child.
  pid = os.fork()

[2025-01-27T22:13:49.619+0000] {standard_task_runner.py:72} INFO - Started process 222 to run task
[2025-01-27T22:13:49.622+0000] {standard_task_runner.py:104} INFO - Running: ['***', 'tasks', 'run', 'raw_api_sales_data', 'store_sales_data_raw', 'manual__2025-01-27T22:12:59.881065+00:00', '--job-id', '55', '--raw', '--subdir', 'DAGS_FOLDER/raw/dag_load_sales_data_to_db.py', '--cfg-path', '/tmp/tmph8u8lk5l']
[2025-01-27T22:13:49.626+0000] {standard_task_runner.py:105} INFO - Job 55: Subtask store_sales_data_raw
[2025-01-27T22:13:49.910+0000] {task_command.py:467} INFO - Running <TaskInstance: raw_api_sales_data.store_sales_data_raw manual__2025-01-27T22:12:59.881065+00:00 [running]> on host 1de8b92bf5f9
[2025-01-27T22:13:50.231+0000] {taskinstance.py:3132} INFO - Exporting env vars: AIRFLOW_CTX_DAG_OWNER='***' AIRFLOW_CTX_DAG_ID='raw_api_sales_data' AIRFLOW_CTX_TASK_ID='store_sales_data_raw' AIRFLOW_CTX_EXECUTION_DATE='2025-01-27T22:12:59.881065+00:00' AIRFLOW_CTX_TRY_NUMBER='1' AIRFLOW_CTX_DAG_RUN_ID='manual__2025-01-27T22:12:59.881065+00:00'
[2025-01-27T22:13:50.235+0000] {logging_mixin.py:190} INFO - Task instance is in running state
[2025-01-27T22:13:50.236+0000] {logging_mixin.py:190} INFO -  Previous state of the Task instance: queued
[2025-01-27T22:13:50.238+0000] {logging_mixin.py:190} INFO - Current task name:store_sales_data_raw state:running start_date:2025-01-27 22:13:49.270818+00:00
[2025-01-27T22:13:50.239+0000] {logging_mixin.py:190} INFO - Dag name:raw_api_sales_data and current dag run status:running
[2025-01-27T22:13:50.240+0000] {taskinstance.py:731} INFO - ::endgroup::
[2025-01-27T22:13:50.560+0000] {database_helpers.py:20} INFO - Connected to PostgreSQL database.
[2025-01-27T22:13:50.562+0000] {database_helpers.py:95} ERROR - Failed to insert data into raw_layer.sales: 'list' object is not callable
[2025-01-27T22:13:50.564+0000] {raw_store_sales_data.py:36} ERROR - Failed to insert data to a table : 'list' object is not callable
[2025-01-27T22:13:50.566+0000] {database_helpers.py:30} INFO - Closed the database connection.
[2025-01-27T22:13:50.569+0000] {raw_store_sales_data.py:40} INFO - Database Closed
[2025-01-27T22:13:50.573+0000] {taskinstance.py:3311} ERROR - Task failed with exception
Traceback (most recent call last):
  File "/home/airflow/.local/lib/python3.12/site-packages/airflow/models/taskinstance.py", line 767, in _execute_task
    result = _execute_callable(context=context, **execute_callable_kwargs)
             ^^^^^^^^^^^^^^^^^^^^^^^^^^^^^^^^^^^^^^^^^^^^^^^^^^^^^^^^^^^^^
  File "/home/airflow/.local/lib/python3.12/site-packages/airflow/models/taskinstance.py", line 733, in _execute_callable
    return ExecutionCallableRunner(
           ^^^^^^^^^^^^^^^^^^^^^^^^
  File "/home/airflow/.local/lib/python3.12/site-packages/airflow/utils/operator_helpers.py", line 252, in run
    return self.func(*args, **kwargs)
           ^^^^^^^^^^^^^^^^^^^^^^^^^^
  File "/home/airflow/.local/lib/python3.12/site-packages/airflow/models/baseoperator.py", line 422, in wrapper
    return func(self, *args, **kwargs)
           ^^^^^^^^^^^^^^^^^^^^^^^^^^^
  File "/home/airflow/.local/lib/python3.12/site-packages/airflow/operators/python.py", line 238, in execute
    return_value = self.execute_callable()
                   ^^^^^^^^^^^^^^^^^^^^^^^
  File "/home/airflow/.local/lib/python3.12/site-packages/airflow/operators/python.py", line 256, in execute_callable
    return runner.run(*self.op_args, **self.op_kwargs)
           ^^^^^^^^^^^^^^^^^^^^^^^^^^^^^^^^^^^^^^^^^^^
  File "/home/airflow/.local/lib/python3.12/site-packages/airflow/utils/operator_helpers.py", line 252, in run
    return self.func(*args, **kwargs)
           ^^^^^^^^^^^^^^^^^^^^^^^^^^
  File "/opt/airflow/dags/logic/raw_store_sales_data.py", line 32, in store_api_sales_data
    insert_data(conn, "raw_layer.sales", columns, records)
  File "/opt/airflow/dags/helpers/database_helpers.py", line 91, in insert_data
    conn.cursor(query, records)
TypeError: 'list' object is not callable
[2025-01-27T22:13:50.669+0000] {logging_mixin.py:190} INFO - Task instance in failure state
[2025-01-27T22:13:50.672+0000] {logging_mixin.py:190} INFO - Task start:2025-01-27 22:13:49.270818+00:00 end:2025-01-27 22:13:50.667235+00:00 duration:1.396417
[2025-01-27T22:13:50.674+0000] {logging_mixin.py:190} INFO - Task:<Task(PythonOperator): store_sales_data_raw> dag:<DAG: raw_api_sales_data> dagrun:<DagRun raw_api_sales_data @ 2025-01-27 22:12:59.881065+00:00: manual__2025-01-27T22:12:59.881065+00:00, state:running, queued_at: 2025-01-27 22:13:01.016211+00:00. externally triggered: True>
[2025-01-27T22:13:50.675+0000] {logging_mixin.py:190} INFO - Failure caused by 'list' object is not callable
[2025-01-27T22:13:50.678+0000] {taskinstance.py:1225} INFO - Marking task as UP_FOR_RETRY. dag_id=raw_api_sales_data, task_id=store_sales_data_raw, run_id=manual__2025-01-27T22:12:59.881065+00:00, execution_date=20250127T221259, start_date=20250127T221349, end_date=20250127T221350
[2025-01-27T22:13:50.747+0000] {taskinstance.py:340} INFO - ::group::Post task execution logs
[2025-01-27T22:13:50.750+0000] {standard_task_runner.py:124} ERROR - Failed to execute job 55 for task store_sales_data_raw ('list' object is not callable; 222)
Traceback (most recent call last):
  File "/home/airflow/.local/lib/python3.12/site-packages/airflow/task/task_runner/standard_task_runner.py", line 117, in _start_by_fork
    ret = args.func(args, dag=self.dag)
          ^^^^^^^^^^^^^^^^^^^^^^^^^^^^^
  File "/home/airflow/.local/lib/python3.12/site-packages/airflow/cli/cli_config.py", line 49, in command
    return func(*args, **kwargs)
           ^^^^^^^^^^^^^^^^^^^^^
  File "/home/airflow/.local/lib/python3.12/site-packages/airflow/utils/cli.py", line 116, in wrapper
    return f(*args, **kwargs)
           ^^^^^^^^^^^^^^^^^^
  File "/home/airflow/.local/lib/python3.12/site-packages/airflow/cli/commands/task_command.py", line 483, in task_run
    task_return_code = _run_task_by_selected_method(args, _dag, ti)
                       ^^^^^^^^^^^^^^^^^^^^^^^^^^^^^^^^^^^^^^^^^^^^
  File "/home/airflow/.local/lib/python3.12/site-packages/airflow/cli/commands/task_command.py", line 256, in _run_task_by_selected_method
    return _run_raw_task(args, ti)
           ^^^^^^^^^^^^^^^^^^^^^^^
  File "/home/airflow/.local/lib/python3.12/site-packages/airflow/cli/commands/task_command.py", line 341, in _run_raw_task
    return ti._run_raw_task(
           ^^^^^^^^^^^^^^^^^
  File "/home/airflow/.local/lib/python3.12/site-packages/airflow/utils/session.py", line 97, in wrapper
    return func(*args, session=session, **kwargs)
           ^^^^^^^^^^^^^^^^^^^^^^^^^^^^^^^^^^^^^^
  File "/home/airflow/.local/lib/python3.12/site-packages/airflow/models/taskinstance.py", line 3005, in _run_raw_task
    return _run_raw_task(
           ^^^^^^^^^^^^^^
  File "/home/airflow/.local/lib/python3.12/site-packages/airflow/models/taskinstance.py", line 273, in _run_raw_task
    TaskInstance._execute_task_with_callbacks(
  File "/home/airflow/.local/lib/python3.12/site-packages/airflow/models/taskinstance.py", line 3159, in _execute_task_with_callbacks
    result = self._execute_task(context, task_orig)
             ^^^^^^^^^^^^^^^^^^^^^^^^^^^^^^^^^^^^^^
  File "/home/airflow/.local/lib/python3.12/site-packages/airflow/models/taskinstance.py", line 3183, in _execute_task
    return _execute_task(self, context, task_orig)
           ^^^^^^^^^^^^^^^^^^^^^^^^^^^^^^^^^^^^^^^
  File "/home/airflow/.local/lib/python3.12/site-packages/airflow/models/taskinstance.py", line 767, in _execute_task
    result = _execute_callable(context=context, **execute_callable_kwargs)
             ^^^^^^^^^^^^^^^^^^^^^^^^^^^^^^^^^^^^^^^^^^^^^^^^^^^^^^^^^^^^^
  File "/home/airflow/.local/lib/python3.12/site-packages/airflow/models/taskinstance.py", line 733, in _execute_callable
    return ExecutionCallableRunner(
           ^^^^^^^^^^^^^^^^^^^^^^^^
  File "/home/airflow/.local/lib/python3.12/site-packages/airflow/utils/operator_helpers.py", line 252, in run
    return self.func(*args, **kwargs)
           ^^^^^^^^^^^^^^^^^^^^^^^^^^
  File "/home/airflow/.local/lib/python3.12/site-packages/airflow/models/baseoperator.py", line 422, in wrapper
    return func(self, *args, **kwargs)
           ^^^^^^^^^^^^^^^^^^^^^^^^^^^
  File "/home/airflow/.local/lib/python3.12/site-packages/airflow/operators/python.py", line 238, in execute
    return_value = self.execute_callable()
                   ^^^^^^^^^^^^^^^^^^^^^^^
  File "/home/airflow/.local/lib/python3.12/site-packages/airflow/operators/python.py", line 256, in execute_callable
    return runner.run(*self.op_args, **self.op_kwargs)
           ^^^^^^^^^^^^^^^^^^^^^^^^^^^^^^^^^^^^^^^^^^^
  File "/home/airflow/.local/lib/python3.12/site-packages/airflow/utils/operator_helpers.py", line 252, in run
    return self.func(*args, **kwargs)
           ^^^^^^^^^^^^^^^^^^^^^^^^^^
  File "/opt/airflow/dags/logic/raw_store_sales_data.py", line 32, in store_api_sales_data
    insert_data(conn, "raw_layer.sales", columns, records)
  File "/opt/airflow/dags/helpers/database_helpers.py", line 91, in insert_data
    conn.cursor(query, records)
TypeError: 'list' object is not callable
[2025-01-27T22:13:50.854+0000] {local_task_job_runner.py:266} INFO - Task exited with return code 1
[2025-01-27T22:13:50.977+0000] {taskinstance.py:3895} INFO - 0 downstream tasks scheduled from follow-on schedule check
[2025-01-27T22:13:50.989+0000] {local_task_job_runner.py:245} INFO - ::endgroup::
